Workbook

Sheet INSTRUCCIONES
B2: NEB-ALCARRIA — Presupuesto
B3: Programa I.B (Actividades demostrativas) — RD 251/2024 — Convocatoria 2026
B5: Versión | C5: 1.0 (2026-05-09)
B6: Tope subvención | C6: 500.000 € (mín. 70.000 €) por propuesta de actividades
B7: Objetivo del proyecto | C7: ~250.000–300.000 € (conservador, margen frente al tope)
B9: Leyenda de colores y formato
B10: Azul | C10: Input (cifra modificable por el usuario)
B11: Negro | C11: Fórmula / cálculo derivado
B12: Verde | C12: Enlace a celda de otra hoja
B13: Fondo amarillo | C13: Hipótesis clave / atención
B14: Fondo verde claro | C14: Total / subtotal
B15: Fondo rojo claro | C15: Tope rebasado (control)
B18: Índice de hojas
B19: 1. PARAMETROS | C19: Fuente única de tarifas, dietas y topes (azul = inputs)
B20: 2. REFERENCIAS_RD | C20: Cita textual del RD/FAQ/Infoday para cada parámetro
B21: 3. ACTIVIDADES | C21: Listado maestro A1–A23 (familia, días, ediciones, asistentes)
B22: 4. PERSONAL | C22: A.1–A.5 (docente, apoyo, coordinación) por actividad
B23: 5. VIAJES | C23: B.1 transporte + alojamiento + manutención por actividad/edición
B24: 6. MATERIALES | C24: B.2–B.7 (entornos, fungible, seguros, auditoría, alquileres, comunicación)
B25: 7. INVERSIONES | C25: C.1 inventariables (amortización) y C.2 otras inversiones
B26: 8. PRESUPUESTO | C26: Resumen final por partida, P1/P2, UPM/COPRODELI, control de topes
B30: Cómo usar
B31: 1. TODOS los parámetros se editan SOLO en la hoja PARAMETROS. Cualquier cambio se propaga al resto.
B32: 2. Las cifras con FONDO AMARILLO son hipótesis nuestras: revísalas antes de presentar la solicitud.
B33: 3. La hoja PRESUPUESTO incluye un panel de control con semáforo: si una celda se pone roja, hay tope rebasado.
B34: 4. Las horas de estudiantes (TE) NO suman al coste de personal (RD: solo asalariados); sí a viajes/dietas.
B35: 5. La amortización C.1 se calcula automáticamente con vida útil del activo y meses de proyecto (17 m).
B36: 6. Para validar el archivo, ejecutar scripts/recalc.py de la skill xlsx tras cualquier cambio importante.

Sheet PARAMETROS
B2: PARAMETROS — fuente única de verdad
B3: Cualquier modificación de tarifas, dietas o topes se hace AQUÍ y se propaga al resto del libro.
B5: A · TARIFAS DE PERSONAL
B6: Concepto | C6: Valor | D6: Unidad | E6: Ref RD | F6: Notas
B7: GP1 con Seguridad Social — Doctor/Licenciado/Ingeniero | C7: 27.98 | D7: €/h | E7: RD-01 | F7: Tope coste/hora personal propio
B8: GP2 con SS — Ing. Técnico/Diplomado | C8: 19.62 | D8: €/h | E8: RD-02
B9: GP3 con SS — Jefes admin/taller, Ayudantes FPII | C9: 16 | D9: €/h | E9: RD-03
B10: GP4 con SS — Auxiliares administrativos | C10: 15.73 | D10: €/h | E10: RD-04
B11: GP5 con SS — Oficial 1ª/2ª/3ª, especialistas, peones | C11: 12.47 | D11: €/h | E11: RD-05 | F11: Albañiles, carpinteros, instaladores
B12: GP1 sin SS | C12: 22.21 | D12: €/h | E12: RD-06
B13: GP5 sin SS | C13: 9.51 | D13: €/h | E13: RD-07
B14: Personal externo (A.1, A.2, A.3 ext.) — IVA excl. | C14: 90 | D14: €/h | E14: RD-08 | F14: Tope uniforme; sin desglose por GP
B15: Tope horas anuales por trabajador | C15: 1720 | D15: h/año | E15: RD-09 | F15: Estándar laboral
B16: Ratio prep. docencia (h prep / h impartida) | C16: 1.5 | D16: ratio | E16: RD-10 | F16: Solo personal docente; NO aplica al apoyo (FAQ 3.34)
B19: B · DIETAS Y KILOMETRAJE (RD 462/2002 grupo 2)
B20: Concepto | C20: Valor | D20: Unidad | E20: Ref RD | F20: Notas
B21: Alojamiento | C21: 65.97 | D21: €/noche/persona | E21: RD-11 | F21: Mismo importe para todo el equipo y participantes
B22: Manutención día completo | C22: 37.4 | D22: €/día/persona | E22: RD-12
B23: Almuerzo o cena | C23: 18.7 | D23: €/persona | E23: RD-13 | F23: FAQ 3.33: aplica si jornada sin pernocta
B24: Locomoción coche particular | C24: 0.26 | D24: €/km | E24: RD-14
B25: Locomoción motocicleta | C25: 0.106 | D25: €/km | E25: RD-15
B28: C · TOPES Y PORCENTAJES
B29: Concepto | C29: Valor | D29: Unidad | E29: Ref RD | F29: Notas
B30: Tope subvención total | C30: 500000 | D30: € | E30: RD-16 | F30: Por propuesta de actividades
B31: Mínimo subvención total | C31: 70000 | D31: € | E31: RD-17 | F31: Si justificas menos, fraude de ley
B32: Tope coordinación (A.5) sobre directos | C32: 0.2 | D32: ratio | E32: RD-18 | F32: Máximo 20 %
B33: Tope viajes (B.1) sobre directos | C33: 0.4 | D33: ratio | E33: RD-19 | F33: Máximo 40 %
B34: Tope inversiones (C.1+C.2) sobre directos | C34: 0.5 | D34: ratio | E34: RD-20 | F34: Máximo 50 %; intensidad 65 %
B35: Tope material fungible (B.3) por participante | C35: 40 | D35: €/part. | E35: RD-21 | F35: Por participante único, no edición
B36: Tope comunicación (B.7) | C36: 1500 | D36: € | E36: RD-22 | F36: Por propuesta
B37: Tope entornos virtuales (B.2) | C37: 5000 | D37: € | E37: RD-23 | F37: Por propuesta
B38: Tope seguros (B.4) | C38: 1000 | D38: € | E38: RD-24 | F38: Por propuesta
B39: Tope auditoría (B.5) | C39: 5000 | D39: € | E39: RD-25 | F39: Máx. 1 % subvención
B40: Tasa indirectos (sobre personal directo) | C40: 0.15 | D40: ratio | E40: RD-26 | F40: Tipo fijo
B41: Intensidad de ayuda (general) | C41: 1 | D41: ratio | E41: RD-27 | F41: 100 % (excepto inversiones C: 65 %)
B42: Intensidad de ayuda inversiones C | C42: 0.65 | D42: ratio | E42: RD-28
B43: Subcontratación — autorización si > 60 k Y > 20 % | C43: 1 | D43: — | E43: RD-29 | F43: Se pide al MAPA
B44: % objetivo presupuesto P1 | C44: 0.3 | D44: ratio | E44: RD-30 | F44: Recomendado por FEGA (informativo)
B45: % objetivo presupuesto P2 | C45: 0.7 | D45: ratio | E45: RD-31 | F45: (informativo)
B46: Meses Periodo 1 (P1) | C46: 7 | D46: meses | E46: — | F46: nov 2026 → may 2027
...

Sheet REFERENCIAS_RD
A1: REFERENCIAS NORMATIVAS — base documental de cada parámetro
A2: Cada fila enlaza un parámetro de PARAMETROS con la cita textual del RD 251/2024, FAQ del MAPA o el Infoday FEGA.
A4: Ref | B4: Concepto | C4: Valor | D4: Cita textual (extracto) | E4: Referencia normativa | F4: Fuente / FAQ | G4: Notas
A5: RD-01 | B5: GP1 con SS | C5: 27,98 €/h | D5: "Coste hora por grupo profesional CON Seguridad Social: GP 1 = 27,98" | E5: RD 251/2024 anexo costes unitarios | F5: Convocatoria 2026 / Resolución FEGA 2-ago-2023 | G5: Doctor, Licenciado, Ingeniero, Arquitecto
A6: RD-02 | B6: GP2 con SS | C6: 19,62 €/h | D6: "GP 2 = 19,62" | E6: idem | F6: idem | G6: Ing. Técnico, Diplomado, Arquitecto Técnico
A7: RD-03 | B7: GP3 con SS | C7: 16,00 €/h | D7: "GP 3 = 16" | E7: idem | F7: idem | G7: Jefes admin/taller, Ayudantes no titulados (FP II)
A8: RD-04 | B8: GP4 con SS | C8: 15,73 €/h | D8: "GP 4 = 15,73" | E8: idem | F8: idem | G8: Auxiliares administrativos
A9: RD-05 | B9: GP5 con SS | C9: 12,47 €/h | D9: "GP 5 = 12,47" | E9: idem | F9: idem | G9: Oficial 1ª/2ª/3ª, especialistas, peones
A10: RD-06 | B10: GP1 sin SS | C10: 22,21 €/h | D10: "Coste hora límite por grupo profesional SIN Seguridad Social: GP 1 = 22,21" | E10: idem | F10: idem | G10: Trabajadores no cotizantes al Régimen General
A11: RD-07 | B11: GP5 sin SS | C11: 9,51 €/h | D11: "GP 5 = 9,51" | E11: idem | F11: idem
A12: RD-08 | B12: Personal externo | C12: 90 €/h IVA excl. | D12: "En el caso del personal docente externo el importe máximo de financiación será de 90 euros la hora, IVA excluido" | E12: RD 251/2024 art. 8.1.a.1 | F12: Convocatoria 2026 | G12: Aplica a personal docente externo (A.1) y apoyo externo (A.2)
A13: RD-09 | B13: Tope horas anuales | C13: 1.720 h/año | D13: "El número máximo de horas serán 1720 horas anuales" | E13: FAQ 3.34 | F13: FAQs Convocatoria 2026 | G13: Personal de apoyo
A14: RD-10 | B14: Ratio preparación docente | C14: 1,5 h prep / h impartida | D14: "podrán contabilizarse las horas de preparación de las actividades hasta un límite de 1,5 horas por hora impartida" | E14: RD 251/2024 art. 8.1.a.1.i | F14: Convocatoria 2026 | G14: SOLO personal docente. NO aplica al personal de apoyo (FAQ 3.34)
A15: RD-11 | B15: Alojamiento | C15: 65,97 €/noche | D15: "alojamiento 65,97 euros/día" | E15: RD 462/2002 grupo 2 | F15: Convocatoria 2026 ap. Quinto.1.a.3º | G15: Mismo importe para personal y participantes
A16: RD-12 | B16: Manutención día completo | C16: 37,40 €/día | D16: "manutención 37,40 euros/día completo" | E16: RD 462/2002 grupo 2 | F16: Convocatoria 2026
A17: RD-13 | B17: Almuerzo / cena | C17: 18,70 € | D17: "18,70 euros/almuerzo o cena" | E17: RD 462/2002 grupo 2 | F17: Convocatoria 2026 / FAQ 3.33 | G17: FAQ 3.33: jornada sin pernocta = aplica media dieta (18,70 €)
A18: RD-14 | B18: Locomoción coche | C18: 0,26 €/km | D18: "0,26 euros/kilómetro recorrido por el uso de automóviles" | E18: RD 462/2002 | F18: Convocatoria 2026
A19: RD-15 | B19: Locomoción moto | C19: 0,106 €/km | D19: "0,106 euros/kilómetro recorrido por el uso de motocicletas" | E19: RD 462/2002 | F19: Convocatoria 2026
A20: RD-16 | B20: Tope subvención total | C20: 500.000 € | D20: Tope máximo por propuesta de actividades | E20: Convocatoria 2026 | F20: Infoday FEGA
A21: RD-17 | B21: Mínimo subvención | C21: 70.000 € | D21: "hemos puesto una iniciativa mínima por propuesta de actividades que son 70.000" | E21: Convocatoria 2026 | F21: Infoday FEGA | G21: Si justificas menos = casi fraude de ley
A22: RD-18 | B22: Tope coordinación | C22: 20 % directos | D22: "Los gastos de personal de coordinación no podrán exceder del 20 % de los gastos directos" | E22: RD 251/2024 art. 8.1.a.1.iii | F22: Convocatoria 2026
A23: RD-19 | B23: Tope viajes y dietas | C23: 40 % directos | D23: "Los gastos de transporte, alojamiento y manutención no podrán exceder el 40 % de los gastos directos" | E23: RD 251/2024 art. 8.1.a.5º | F23: Convocatoria 2026 | G23: Acumulado: personal + participantes + estudiantes
A24: RD-20 | B24: Tope inversiones | C24: 50 % directos · intensidad 65 % | D24: "importe máximo para la adquisición de estos bienes inventariables será de un 50 % de los gastos directos…intensidad de ayuda máxima del 65 %" | E24: RD 251/2024 art. 8.1.a.10º | F24: Convocatoria 2026 ap. Quinto | G24: Aplica a C.1 + C.2 conjuntamente
A25: RD-21 | B25: Tope material fungible (B.3) | C25: 40 €/participante | D25: "Máximo subvencionable de 40 euros por participante" | E25: RD 251/2024 art. 8.1.a.5º | F25: Convocatoria 2026 | G25: Por participante único TOTAL del proyecto, no por edición
A26: RD-22 | B26: Tope comunicación (B.7) | C26: 1.500 € | D26: "Se establece un límite máximo de 1.500 euros por propuesta de actividades" | E26: RD 251/2024 art. 8.1.c | F26: Convocatoria 2026 | G26: Roll-ups, folletos, web, RRSS
A27: RD-23 | B27: Tope entornos virtuales (B.2) | C27: 5.000 € | D27: "Se establece un límite máximo de 5.000 euros por Propuesta de Actividades" | E27: Convocatoria 2026
A28: RD-24 | B28: Tope seguros (B.4) | C28: 1.000 € | D28: Tope partida B.4 | E28: Convocatoria 2026 | F28: Anexo XXII
A29: RD-25 | B29: Tope auditoría (B.5) | C29: 5.000 € · 1 % subvención | D29: Auditor: 1 % subvención concedida, máx. 5.000 € | E29: Convocatoria 2026
A30: RD-26 | B30: Tasa indirectos | C30: 15 % personal directo | D30: "Estos costes se calcularán a un tipo fijo del 15 % de los costes directos de personal subvencionables" | E30: RD 251/2024 art. 8.1.b | F30: Convocatoria 2026 | G30: Por analogía art. 54.b Reg. UE 2021/1060
A31: RD-27 | B31: Intensidad ayuda general | C31: 100 % | D31: Intensidad ayuda al 100 % salvo C | E31: Convocatoria 2026 | F31: Infoday FEGA
A32: RD-28 | B32: Intensidad ayuda C | C32: 65 % | D32: "intensidad de ayuda máxima del 65 %" | E32: RD 251/2024 art. 8.1.a.10º | F32: Convocatoria 2026
A33: RD-29 | B33: Subcontratación | C33: autorización si > 60.000 € Y > 20 % | D33: "la subcontratación de entidades vinculadas y las subcontrataciones elevadas que es pedir más de 60.000 € y más de un 20 %" | E33: Ley General Subvenciones | F33: Infoday FEGA
A34: RD-30 | B34: Distribución P1 / P2 | C34: 30 / 70 | D34: "recomendamos que dividáis vuestro presupuesto en un 30 % para el primer periodo de ejecución y en un 70 %" | E34: Convocatoria 2026 | F34: Infoday FEGA | G34: Recomendación; no obligatorio
A35: FAQ-3.34 | B35: Personal de apoyo NO sujeto a 1,5 h prep | C35: — | D35: "se define al personal de apoyo como personal 'no docente' por lo que no aplica dicha consideración" | E35: FAQ 3.34 | F35: FAQs Convocatoria 2026 | G35: Novedad 2026: importante para acondicionamiento Living Lab
A36: FAQ-3.33 | B36: Media dieta sin pernocta | C36: 18,70 € | D36: "jornada (6 horas) sin pernoctación… aplica… media dieta" | E36: FAQ 3.33 | F36: FAQs Convocatoria 2026
A37: FAQ-IB-DUR | B37: Actividad demostrativa ≤ 2 días | C37: — | D37: "demostraciones presenciales, de corta duración (no superior a dos días)" | E37: Anexo II.B plantilla | F37: Plantilla Convocatoria 2026 | G37: Hay que descomponer el proyecto en jornadas demostrativas de ≤ 2 días
A38: FAQ-PRESEN | B38: I.B = 100 % presencial | C38: — | D38: "las actividades demostrativas… solo son presenciales, no se puede hacer demostraciones online" | E38: Infoday FEGA
A39: FAQ-PART | B39: Mínimo participantes | C39: 10 / actividad | D39: "todas las actividades… deben de contar con un mínimo de 10 participantes" | E39: Guía del Solicitante | F39: Infoday FEGA
A40: AMORT | B40: Amortización C.1 = solo periodo subvencionable | C40: — | D40: "La amortización correspondiente al periodo subvencionable en caso de compra de nueva maquinaria y equipo" | E40: RD 251/2024 art. 8.1.a.10º.i | F40: Convocatoria 2026 | G40: NO se imputa el 100 % de la compra; sólo cuota

Sheet ACTIVIDADES
A1: ACTIVIDADES — listado maestro A1–A23
A2: Asistencias totales = (Asist. prof + Asist. estud) × Ediciones. Inputs en azul.
A4: Id | B4: Familia | C4: Actividad | D4: Días | E4: Ediciones | F4: Asist. prof./ed. | G4: Asist. estud./ed. | H4: Asist. total | I4: Periodo | J4: Ventana
A5: A1 | B5: F1 · Concepto NEB | C5: Concepto NEB aplicado a la microexplotación alcarreña | D5: 1 | E5: 1 | F5: 15 | G5: 5 | H5: =(F5+G5)*E5 -> 20 | I5: P1 | J5: ene 2027
A6: A2 | B6: F2 · CUE+SIG | C6: Cumplimentación CUE/SIEX | D6: 2 | E6: 2 | F6: 18 | G6: 4 | H6: =(F6+G6)*E6 -> 44 | I6: P1+P2 | J6: feb · sep 2027
A7: A3 | B7: F2 · CUE+SIG | C7: SIGPAC y declaración | D7: 1 | E7: 1 | F7: 18 | G7: 4 | H7: =(F7+G7)*E7 -> 22 | I7: P1 | J7: mar 2027
A8: A4 | B8: F2 · CUE+SIG | C8: SIG QGIS + NDVI en campo | D8: 2 | E8: 1 | F8: 15 | G8: 5 | H8: =(F8+G8)*E8 -> 20 | I8: P1 | J8: abr 2027
A9: A5 | B9: F3 · IoT+riego | C9: Despliegue red IoT en huerta | D9: 2 | E9: 1 | F9: 12 | G9: 6 | H9: =(F9+G9)*E9 -> 18 | I9: P2 | J9: sep 2027
A10: A6 | B10: F3 · IoT+riego | C10: Demostración riego automatizado | D10: 1 | E10: 2 | F10: 15 | G10: 5 | H10: =(F10+G10)*E10 -> 40 | I10: P2 | J10: oct 2027 · feb 2028
A11: A7 | B11: F3 · IoT+riego | C11: Volcado automatizado al CUE | D11: 1 | E11: 1 | F11: 15 | G11: 4 | H11: =(F11+G11)*E11 -> 19 | I11: P2 | J11: oct 2027
A12: A8 | B12: F4 · Diseño digital | C12: CAD instalaciones de madera | D12: 2 | E12: 1 | F12: 12 | G12: 6 | H12: =(F12+G12)*E12 -> 18 | I12: P1 | J12: may 2027
A13: A9 | B13: F4 · Diseño digital | C13: Cálculo y planos del domo geodésico | D13: 1 | E13: 1 | F13: 12 | G13: 6 | H13: =(F13+G13)*E13 -> 18 | I13: P1 | J13: may 2027
A14: A10 | B14: F5 · Domo NEB | C14: Levantamiento de la estructura del domo | D14: 2 | E14: 1 | F14: 12 | G14: 8 | H14: =(F14+G14)*E14 -> 20 | I14: P2 | J14: jul 2027
A15: A11 | B15: F5 · Domo NEB | C15: Anclajes y fijaciones del domo | D15: 1 | E15: 1 | F15: 12 | G15: 8 | H15: =(F15+G15)*E15 -> 20 | I15: P2 | J15: jul 2027
A16: A12 | B16: F5 · Domo NEB | C16: Cubierta y entelado del domo | D16: 2 | E16: 1 | F16: 12 | G16: 8 | H16: =(F16+G16)*E16 -> 20 | I16: P2 | J16: jul–ago 2027
... A29: A25 | B29: F10 · Software open-source | C29: Configuración del SIG open-source (QGIS + QField) para microexplotaciones (TRL5 → TRL7) | D29: 1 | E29: 1 | F29: 12 | G29: 6 | H29: =(F29+G29)*E29 -> 18 | I29: P1 | J29: abr 2027
C30: TOTAL | E30: =SUM(E5:E29) -> 28 | H30: =SUM(H5:H29) -> 565
A33: Cómo se usan estos números
B34: Asistencias totales (col. H) | C34: Fórmula: (Asist. prof./ed. + Asist. estud./ed.) × Ediciones. Es la cifra de "asistencias-edición" del proyecto, NO de personas únicas.
B35: Viajes y dietas (B.1) | C35: Multiplican el aforo total por las dietas oficiales: 37,40 €/día completo · 18,70 €/media · 65,97 €/noche · 0,26 €/km. Hoja VIAJES.
B36: Material fungible (B.3) | C36: Tope 40 €/participante ÚNICO del proyecto (no por edición). Estimación 60–90 únicos al final → 2.400–3.600 €.
B37: Anexo II.B sec. 3.4 «Usuarios finales» | C37: Criterio B2 del baremo. Hay que justificar el perfil y la cifra. Las dos columnas alimentan directamente esa justificación.
B38: Mínimo legal | C38: FEGA: ≥ 10 participantes/edición. Todas nuestras actividades lo cumplen con holgura (la más baja, 16).
A40: Por qué separamos profesionales y estudiantes
B41: Exigencia del RD 251/2024 | C41: Programa I.B exige destinatarios finales = "profesionales del sector agroalimentario o forestal" (agricultores activos, técnicos, asesores, gestores de explotación, cooperativas).
B42: Estudiantes admitidos como "futuros profesionales" | C42: FAQ del MAPA: los alumnos UPM en prácticas computan como "futuros profesionales del sector agroforestal", pero el evaluador valora el RATIO.
B43: Tratamiento económico (asistentes) | C43: IGUAL para ambos: NI profesionales NI estudiantes cobran por asistir (son destinatarios, no personal). A AMBOS se les pueden pagar viajes, manutención y alojamiento con cargo a B.1.
B44: Distinción prof / est = normativa, no económica | C44: Sirve para justificar el perfil de los destinatarios en la sec. 3.4 del Anexo II.B (criterio B2) y para defender el ratio ante el evaluador.
B45: Ratio defendible | C45: Si el grueso fueran estudiantes, el evaluador podría descalificar la propuesta como "no transferencia al sector". Mantener al menos ~70 % profesionales.
B46: Caso aparte: estudiantes como colaboradores no remunerados | C46: Si un estudiante aporta TRABAJO físico al acondicionamiento del Living Lab (precorte de madera, cableado IoT, etc.), figura en las columnas "h Estud. UPM" y "h Estud. COPR" de la hoja PERSONAL. Sus horas NO se imputan a A.4 (no son asalariados, RD art. 8.1.a.1) pero se reflejan para mostrar el esfuerzo total del proyecto y reforzar la innovación interactiva multiactor.
A48: Cifras actuales por familia y por qué son así
B49: Familia | C49: Actividades | D49: prof./ed. | E49: est./ed. | F49: Edic. | G49: Razón
B50: F1 · Concepto NEB | C50: A1 | D50: 15 | E50: 5 | F50: 1 | G50: Jornada de lanzamiento abierta a la comunidad
B51: F2 · CUE + SIG | C51: A2 · A3 · A4 | D51: 15-18 | E51: 4-5 | F51: 1-2 | G51: Núcleo del baremo (línea estratégica A: CUE). Alto peso de profesionales.
B52: F3 · IoT + riego | C52: A5 · A6 · A7 | D52: 12-15 | E52: 4-6 | F52: 1-2 | G52: Técnico avanzado, audiencia más nicho. Mix prof/est equilibrado.
B53: F4 · Diseño digital | C53: A8 · A9 | D53: 12 | E53: 6 | F53: 1 | G53: CAD y cálculo del domo: sesgo académico, más estudiantes.
B54: F5 · Domo NEB | C54: A10–A13 | D54: 12 | E54: 8 | F54: 1 | G54: Co-construcción manual: muchos estudiantes implicados (innovación interactiva).
B55: F6 · Equipamiento | C55: A14 · A15 | D55: 12 | E55: 4 | F55: 1 | G55: Instalación técnica puntual (FV + telecom).
B56: F7 · Despliegue terreno | C56: A16 · A17 | D56: 12-15 | E56: 5-6 | F56: 1-2 | G56: Sensores en parcela y vuelo dronístico. Mixto.
B57: F8 · Ciclo productivo | C57: A18–A22 | D57: 15 | E57: 5 | F57: 1 | G57: Profesionales del sector hortícola (target principal del RD).
...

Sheet PERSONAL
A1: PERSONAL — A.1 · A.2 · A.3 · A.4 · A.5
A2: Inputs en azul. Tarifas €/h se toman de PARAMETROS (GP1 = ingenieros · GP5 = oficiales). Las horas de estudiantes no generan coste (no remunerados).
A4: A.4 · PERSONAL DE APOYO PROPIO (acondicionamiento Living Lab) — GP1 y GP5 según tabla de salarios (PARAMETROS)
A5: Id | B5: Familia | C5: h GP1 UPM | D5: h GP1 COPR | E5: h GP5 UPM | F5: h GP5 COPR | G5: h Estud. UPM | H5: h Estud. COPR | I5: Coste UPM | J5: Coste COPR | K5: Coste total
A6: A1 | B6: =VLOOKUP(A6,ACTIVIDADES!$A$5:$B$50,2,FALSE()) -> F1 · Concepto NEB | C6: 2 | D6: 2 | E6: 1 | F6: 1 | G6: 2 | H6: 0 | I6: =C6*gp1_ss+E6*gp5_ss -> 68.43 | J6: =D6*gp1_ss+F6*gp5_ss -> 68.43 | K6: =I6+J6 -> 136.86
A7: A2 | B7: =VLOOKUP(A7,ACTIVIDADES!$A$5:$B$50,2,FALSE()) -> F2 · CUE+SIG | C7: 33 | D7: 7 | E7: 7 | F7: 1 | G7: 6 | H7: 0 | I7: =C7*gp1_ss+E7*gp5_ss -> 1010.63 | J7: =D7*gp1_ss+F7*gp5_ss -> 208.33 | K7: =I7+J7 -> 1218.96
A8: A3 | B8: =VLOOKUP(A8,ACTIVIDADES!$A$5:$B$50,2,FALSE()) -> F2 · CUE+SIG | C8: 14 | D8: 2 | E8: 4 | F8: 0 | G8: 4 | H8: 0 | I8: =C8*gp1_ss+E8*gp5_ss -> 441.6 | J8: =D8*gp1_ss+F8*gp5_ss -> 55.96 | K8: =I8+J8 -> 497.56
A9: A4 | B9: =VLOOKUP(A9,ACTIVIDADES!$A$5:$B$50,2,FALSE()) -> F2 · CUE+SIG | C9: 18 | D9: 4 | E9: 4 | F9: 0 | G9: 6 | H9: 0 | I9: =C9*gp1_ss+E9*gp5_ss -> 553.52 | J9: =D9*gp1_ss+F9*gp5_ss -> 111.92 | K9: =I9+J9 -> 665.44
A10: A5 | B10: =VLOOKUP(A10,ACTIVIDADES!$A$5:$B$50,2,FALSE()) -> F3 · IoT+riego | C10: 30 | D10: 20 | E10: 12 | F10: 8 | G10: 10 | H10: 0 | I10: =C10*gp1_ss+E10*gp5_ss -> 989.04 | J10: =D10*gp1_ss+F10*gp5_ss -> 659.36 | K10: =I10+J10 -> 1648.4
A11: A6 | B11: =VLOOKUP(A11,ACTIVIDADES!$A$5:$B$50,2,FALSE()) -> F3 · IoT+riego | C11: 12 | D11: 8 | E11: 5 | F11: 3 | G11: 4 | H11: 0 | I11: =C11*gp1_ss+E11*gp5_ss -> 398.11 | J11: =D11*gp1_ss+F11*gp5_ss -> 261.25 | K11: =I11+J11 -> 659.36
A12: A7 | B12: =VLOOKUP(A12,ACTIVIDADES!$A$5:$B$50,2,FALSE()) -> F3 · IoT+riego | C12: 8 | D12: 4 | E12: 0 | F12: 0 | G12: 4 | H12: 0 | I12: =C12*gp1_ss+E12*gp5_ss -> 223.84 | J12: =D12*gp1_ss+F12*gp5_ss -> 111.92 | K12: =I12+J12 -> 335.76
A13: A8 | B13: =VLOOKUP(A13,ACTIVIDADES!$A$5:$B$50,2,FALSE()) -> F4 · Diseño digital | C13: 4 | D13: 2 | E13: 0 | F13: 0 | G13: 2 | H13: 0 | I13: =C13*gp1_ss+E13*gp5_ss -> 111.92 | J13: =D13*gp1_ss+F13*gp5_ss -> 55.96 | K13: =I13+J13 -> 167.88
A14: A9 | B14: =VLOOKUP(A14,ACTIVIDADES!$A$5:$B$50,2,FALSE()) -> F4 · Diseño digital | C14: 4 | D14: 2 | E14: 0 | F14: 0 | G14: 2 | H14: 0 | I14: =C14*gp1_ss+E14*gp5_ss -> 111.92 | J14: =D14*gp1_ss+F14*gp5_ss -> 55.96 | K14: =I14+J14 -> 167.88
A15: A10 | B15: =VLOOKUP(A15,ACTIVIDADES!$A$5:$B$50,2,FALSE()) -> F5 · Domo NEB | C15: 10 | D15: 22 | E15: 30 | F15: 70 | G15: 28 | H15: 0 | I15: =C15*gp1_ss+E15*gp5_ss -> 653.9 | J15: =D15*gp1_ss+F15*gp5_ss -> 1488.46 | K15: =I15+J15 -> 2142.36
A16: A11 | B16: =VLOOKUP(A16,ACTIVIDADES!$A$5:$B$50,2,FALSE()) -> F5 · Domo NEB | C16: 5 | D16: 11 | E16: 14 | F16: 34 | G16: 16 | H16: 0 | I16: =C16*gp1_ss+E16*gp5_ss -> 314.48 | J16: =D16*gp1_ss+F16*gp5_ss -> 731.76 | K16: =I16+J16 -> 1046.24
A17: A12 | B17: =VLOOKUP(A17,ACTIVIDADES!$A$5:$B$50,2,FALSE()) -> F5 · Domo NEB | C17: 2 | D17: 6 | E17: 7 | F17: 17 | G17: 8 | H17: 0 | I17: =C17*gp1_ss+E17*gp5_ss -> 143.25 | J17: =D17*gp1_ss+F17*gp5_ss -> 379.87 | K17: =I17+J17 -> 523.12
... A30: A25 | B30: =VLOOKUP(A30,ACTIVIDADES!$A$5:$B$50,2,FALSE()) -> F10 · Software open-source | C30: 325 | D30: 0 | E30: 50 | F30: 0 | G30: 30 | H30: 0 | I30: =C30*gp1_ss+E30*gp5_ss -> 9717 | J30: =D30*gp1_ss+F30*gp5_ss -> 0 | K30: =I30+J30 -> 9717
B31: TOTAL A.4 | C31: =SUM(C6:C30) -> 876 | D31: =SUM(D6:D30) -> 161 | E31: =SUM(E6:E30) -> 247 | F31: =SUM(F6:F30) -> 241 | G31: =SUM(G6:G30) -> 242 | H31: =SUM(H6:H30) -> 0 | I31: =SUM(I6:I30) -> 27590.57 | J31: =SUM(J6:J30) -> 7510.05 | K31: =SUM(K6:K30) -> 35100.62
A34: A.3 · PERSONAL DOCENTE PROPIO — GP1 (ponentes UPM/COPRODELI). h prep solo 1ª edición (ratio 1,5×).
A35: Id | B35: Familia | C35: h doc UPM | D35: h doc COPR | E35: h prep UPM | F35: h prep COPR | G35: Total h UPM | H35: Total h COPR | I35: Coste UPM | J35: Coste COPR | K35: Coste total
A36: A1 | B36: =VLOOKUP(A36,ACTIVIDADES!$A$5:$B$50,2,FALSE()) -> F1 · Concepto NEB | C36: 2 | D36: 4 | E36: 4 | F36: 5 | G36: =C36+E36 -> 6 | H36: =D36+F36 -> 9 | I36: =G36*gp1_ss -> 167.88 | J36: =H36*gp1_ss -> 251.82 | K36: =I36+J36 -> 419.7
A37: A2 | B37: =VLOOKUP(A37,ACTIVIDADES!$A$5:$B$50,2,FALSE()) -> F2 · CUE+SIG | C37: 20 | D37: 4 | E37: 15 | F37: 3 | G37: =C37+E37 -> 35 | H37: =D37+F37 -> 7 | I37: =G37*gp1_ss -> 979.3 | J37: =H37*gp1_ss -> 195.86 | K37: =I37+J37 -> 1175.16
A38: A3 | B38: =VLOOKUP(A38,ACTIVIDADES!$A$5:$B$50,2,FALSE()) -> F2 · CUE+SIG | C38: 5 | D38: 1 | E38: 8 | F38: 1 | G38: =C38+E38 -> 13 | H38: =D38+F38 -> 2 | I38: =G38*gp1_ss -> 363.74 | J38: =H38*gp1_ss -> 55.96 | K38: =I38+J38 -> 419.7
A39: A4 | B39: =VLOOKUP(A39,ACTIVIDADES!$A$5:$B$50,2,FALSE()) -> F2 · CUE+SIG | C39: 10 | D39: 2 | E39: 15 | F39: 3 | G39: =C39+E39 -> 25 | H39: =D39+F39 -> 5 | I39: =G39*gp1_ss -> 699.5 | J39: =H39*gp1_ss -> 139.9 | K39: =I39+J39 -> 839.4
A40: A5 | B40: =VLOOKUP(A40,ACTIVIDADES!$A$5:$B$50,2,FALSE()) -> F3 · IoT+riego | C40: 10 | D40: 2 | E40: 15 | F40: 3 | G40: =C40+E40 -> 25 | H40: =D40+F40 -> 5 | I40: =G40*gp1_ss -> 699.5 | J40: =H40*gp1_ss -> 139.9 | K40: =I40+J40 -> 839.4
A41: A6 | B41: =VLOOKUP(A41,ACTIVIDADES!$A$5:$B$50,2,FALSE()) -> F3 · IoT+riego | C41: 10 | D41: 2 | E41: 8 | F41: 1 | G41: =C41+E41 -> 18 | H41: =D41+F41 -> 3 | I41: =G41*gp1_ss -> 503.64 | J41: =H41*gp1_ss -> 83.94 | K41: =I41+J41 -> 587.58
A42: A7 | B42: =VLOOKUP(A42,ACTIVIDADES!$A$5:$B$50,2,FALSE()) -> F3 · IoT+riego | C42: 5 | D42: 1 | E42: 8 | F42: 1 | G42: =C42+E42 -> 13 | H42: =D42+F42 -> 2 | I42: =G42*gp1_ss -> 363.74 | J42: =H42*gp1_ss -> 55.96 | K42: =I42+J42 -> 419.7
A43: A8 | B43: =VLOOKUP(A43,ACTIVIDADES!$A$5:$B$50,2,FALSE()) -> F4 · Diseño digital | C43: 10 | D43: 2 | E43: 15 | F43: 3 | G43: =C43+E43 -> 25 | H43: =D43+F43 -> 5 | I43: =G43*gp1_ss -> 699.5 | J43: =H43*gp1_ss -> 139.9 | K43: =I43+J43 -> 839.4
A44: A9 | B44: =VLOOKUP(A44,ACTIVIDADES!$A$5:$B$50,2,FALSE()) -> F4 · Diseño digital | C44: 5 | D44: 1 | E44: 8 | F44: 1 | G44: =C44+E44 -> 13 | H44: =D44+F44 -> 2 | I44: =G44*gp1_ss -> 363.74 | J44: =H44*gp1_ss -> 55.96 | K44: =I44+J44 -> 419.7
A45: A10 | B45: =VLOOKUP(A45,ACTIVIDADES!$A$5:$B$50,2,FALSE()) -> F5 · Domo NEB | C45: 6 | D45: 6 | E45: 9 | F45: 9 | G45: =C45+E45 -> 15 | H45: =D45+F45 -> 15 | I45: =G45*gp1_ss -> 419.7 | J45: =H45*gp1_ss -> 419.7 | K45: =I45+J45 -> 839.4
A46: A11 | B46: =VLOOKUP(A46,ACTIVIDADES!$A$5:$B$50,2,FALSE()) -> F5 · Domo NEB | C46: 3 | D46: 3 | E46: 5 | F46: 4 | G46: =C46+E46 -> 8 | H46: =D46+F46 -> 7 | I46: =G46*gp1_ss -> 223.84 | J46: =H46*gp1_ss -> 195.86 | K46: =I46+J46 -> 419.7
A47: A12 | B47: =VLOOKUP(A47,ACTIVIDADES!$A$5:$B$50,2,FALSE()) -> F5 · Domo NEB | C47: 6 | D47: 6 | E47: 9 | F47: 9 | G47: =C47+E47 -> 15 | H47: =D47+F47 -> 15 | I47: =G47*gp1_ss -> 419.7 | J47: =H47*gp1_ss -> 419.7 | K47: =I47+J47 -> 839.4
... A60: A25 | B60: =VLOOKUP(A60,ACTIVIDADES!$A$5:$B$50,2,FALSE()) -> F10 · Software open-source | C60: 6 | D60: 0 | E60: 9 | F60: 0 | G60: =C60+E60 -> 15 | H60: =D60+F60 -> 0 | I60: =G60*gp1_ss -> 419.7 | J60: =H60*gp1_ss -> 0 | K60: =I60+J60 -> 419.7
B61: TOTAL A.3 | C61: =SUM(C36:C60) -> 147 | D61: =SUM(D36:D60) -> 69 | E61: =SUM(E36:E60) -> 196 | F61: =SUM(F36:F60) -> 92 | G61: =SUM(G36:G60) -> 343 | H61: =SUM(H36:H60) -> 161 | I61: =SUM(I36:I60) -> 9597.14 | J61: =SUM(J36:J60) -> 4504.78 | K61: =SUM(K36:K60) -> 14101.92
A64: A.1 · PERSONAL DOCENTE EXTERNO (ponentes invitados) — 90 €/h IVA excl.
A65: Id | B65: Concepto | C65: h ext. UPM | D65: h ext. COPR | E65: Total h | F65: Coste UPM | G65: Coste COPR | H65: Coste total
A66: A1 | B66: Ponente invitado NEB europeo (proyecto-hermano) | C66: 4 | D66: 4 | E66: =C66+D66 -> 8 | F66: =C66*ext_h -> 360 | G66: =D66*ext_h -> 360 | H66: =F66+G66 -> 720
A67: A23 | B67: Ponente externo cierre / evaluación AKIS | C67: 3 | D67: 3 | E67: =C67+D67 -> 6 | F67: =C67*ext_h -> 270 | G67: =D67*ext_h -> 270 | H67: =F67+G67 -> 540
B68: TOTAL A.1 | C68: =SUM(C66:C67) -> 7 | D68: =SUM(D66:D67) -> 7 | E68: =SUM(E66:E67) -> 14 | F68: =SUM(F66:F67) -> 630 | G68: =SUM(G66:G67) -> 630 | H68: =SUM(H66:H67) -> 1260
A71: A.2 · PERSONAL DE APOYO EXTERNO (carpinteros, instaladores subcontratados) — 90 €/h IVA excl.
...

Sheet VIAJES
A1: VIAJES — B.1 · Transporte + alojamiento + manutención (RD 462/2002 grupo 2)
A2: Una fila por edición. Tutores UPM viajan desde Madrid; tutores COPRODELI son LOCALES (solo manutención). "Periodo" en azul: input editable (default según ventana). Tope global B.1 = 40 % directos.
A4: Id | B4: Edic. | C4: Días | D4: Asist. prof | E4: Asist. estud | F4: Tutor UPM | G4: Tutor COPR | H4: Total comen | I4: Total bus+aloj | J4: Pernoctas | K4: Manutención € | L4: Alojamiento € | M4: Transporte € | N4: Total € | O4: UPM % | P4: UPM € | Q4: COPR € | R4: Periodo
A5: A1 | B5: 1 | C5: =VLOOKUP(A5,ACTIVIDADES!$A$5:$D$50,4,FALSE()) -> 1 | D5: =VLOOKUP(A5,ACTIVIDADES!$A$5:$F$50,6,FALSE()) -> 15 | E5: =VLOOKUP(A5,ACTIVIDADES!$A$5:$G$50,7,FALSE()) -> 5 | F5: 1 | G5: 1 | H5: =D5+E5+F5+G5 -> 22 | I5: =D5+E5+F5 -> 21 | J5: 0 | K5: =H5*(J5*manut_dia+(C5-J5)*manut_med) -> 411.4 | L5: =I5*J5*alojamiento -> 0 | M5: =C5*bus_dia*CEILING(I5/cap_bus,1) -> 700 | N5: =K5+L5+M5 -> 1111.4 | O5: 0.4 | P5: =N5*O5 -> 444.56 | Q5: =N5*(1-O5) -> 666.84 | R5: P1
A6: A2 | B6: 1 | C6: =VLOOKUP(A6,ACTIVIDADES!$A$5:$D$50,4,FALSE()) -> 2 | D6: =VLOOKUP(A6,ACTIVIDADES!$A$5:$F$50,6,FALSE()) -> 18 | E6: =VLOOKUP(A6,ACTIVIDADES!$A$5:$G$50,7,FALSE()) -> 4 | F6: 1 | G6: 1 | H6: =D6+E6+F6+G6 -> 24 | I6: =D6+E6+F6 -> 23 | J6: 1 | K6: =H6*(J6*manut_dia+(C6-J6)*manut_med) -> 1346.4 | L6: =I6*J6*alojamiento -> 1517.31 | M6: =C6*bus_dia*CEILING(I6/cap_bus,1) -> 1400 | N6: =K6+L6+M6 -> 4263.71 | O6: 0.7 | P6: =N6*O6 -> 2984.597 | Q6: =N6*(1-O6) -> 1279.113 | R6: P1
A7: A2 | B7: 2 | C7: =VLOOKUP(A7,ACTIVIDADES!$A$5:$D$50,4,FALSE()) -> 2 | D7: =VLOOKUP(A7,ACTIVIDADES!$A$5:$F$50,6,FALSE()) -> 18 | E7: =VLOOKUP(A7,ACTIVIDADES!$A$5:$G$50,7,FALSE()) -> 4 | F7: 1 | G7: 1 | H7: =D7+E7+F7+G7 -> 24 | I7: =D7+E7+F7 -> 23 | J7: 1 | K7: =H7*(J7*manut_dia+(C7-J7)*manut_med) -> 1346.4 | L7: =I7*J7*alojamiento -> 1517.31 | M7: =C7*bus_dia*CEILING(I7/cap_bus,1) -> 1400 | N7: =K7+L7+M7 -> 4263.71 | O7: 0.7 | P7: =N7*O7 -> 2984.597 | Q7: =N7*(1-O7) -> 1279.113 | R7: P2
A8: A3 | B8: 1 | C8: =VLOOKUP(A8,ACTIVIDADES!$A$5:$D$50,4,FALSE()) -> 1 | D8: =VLOOKUP(A8,ACTIVIDADES!$A$5:$F$50,6,FALSE()) -> 18 | E8: =VLOOKUP(A8,ACTIVIDADES!$A$5:$G$50,7,FALSE()) -> 4 | F8: 1 | G8: 1 | H8: =D8+E8+F8+G8 -> 24 | I8: =D8+E8+F8 -> 23 | J8: 0 | K8: =H8*(J8*manut_dia+(C8-J8)*manut_med) -> 448.8 | L8: =I8*J8*alojamiento -> 0 | M8: =C8*bus_dia*CEILING(I8/cap_bus,1) -> 700 | N8: =K8+L8+M8 -> 1148.8 | O8: 0.7 | P8: =N8*O8 -> 804.16 | Q8: =N8*(1-O8) -> 344.64 | R8: P1
A9: A4 | B9: 1 | C9: =VLOOKUP(A9,ACTIVIDADES!$A$5:$D$50,4,FALSE()) -> 2 | D9: =VLOOKUP(A9,ACTIVIDADES!$A$5:$F$50,6,FALSE()) -> 15 | E9: =VLOOKUP(A9,ACTIVIDADES!$A$5:$G$50,7,FALSE()) -> 5 | F9: 1 | G9: 1 | H9: =D9+E9+F9+G9 -> 22 | I9: =D9+E9+F9 -> 21 | J9: 1 | K9: =H9*(J9*manut_dia+(C9-J9)*manut_med) -> 1234.2 | L9: =I9*J9*alojamiento -> 1385.37 | M9: =C9*bus_dia*CEILING(I9/cap_bus,1) -> 1400 | N9: =K9+L9+M9 -> 4019.57 | O9: 0.7 | P9: =N9*O9 -> 2813.699 | Q9: =N9*(1-O9) -> 1205.871 | R9: P1
A10: A5 | B10: 1 | C10: =VLOOKUP(A10,ACTIVIDADES!$A$5:$D$50,4,FALSE()) -> 2 | D10: =VLOOKUP(A10,ACTIVIDADES!$A$5:$F$50,6,FALSE()) -> 12 | E10: =VLOOKUP(A10,ACTIVIDADES!$A$5:$G$50,7,FALSE()) -> 6 | F10: 2 | G10: 1 | H10: =D10+E10+F10+G10 -> 21 | I10: =D10+E10+F10 -> 20 | J10: 1 | K10: =H10*(J10*manut_dia+(C10-J10)*manut_med) -> 1178.1 | L10: =I10*J10*alojamiento -> 1319.4 | M10: =C10*bus_dia*CEILING(I10/cap_bus,1) -> 1400 | N10: =K10+L10+M10 -> 3897.5 | O10: 0.6 | P10: =N10*O10 -> 2338.5 | Q10: =N10*(1-O10) -> 1559 | R10: P2
A11: A6 | B11: 1 | C11: =VLOOKUP(A11,ACTIVIDADES!$A$5:$D$50,4,FALSE()) -> 1 | D11: =VLOOKUP(A11,ACTIVIDADES!$A$5:$F$50,6,FALSE()) -> 15 | E11: =VLOOKUP(A11,ACTIVIDADES!$A$5:$G$50,7,FALSE()) -> 5 | F11: 1 | G11: 1 | H11: =D11+E11+F11+G11 -> 22 | I11: =D11+E11+F11 -> 21 | J11: 0 | K11: =H11*(J11*manut_dia+(C11-J11)*manut_med) -> 411.4 | L11: =I11*J11*alojamiento -> 0 | M11: =C11*bus_dia*CEILING(I11/cap_bus,1) -> 700 | N11: =K11+L11+M11 -> 1111.4 | O11: 0.6 | P11: =N11*O11 -> 666.84 | Q11: =N11*(1-O11) -> 444.56 | R11: P2
A12: A6 | B12: 2 | C12: =VLOOKUP(A12,ACTIVIDADES!$A$5:$D$50,4,FALSE()) -> 1 | D12: =VLOOKUP(A12,ACTIVIDADES!$A$5:$F$50,6,FALSE()) -> 15 | E12: =VLOOKUP(A12,ACTIVIDADES!$A$5:$G$50,7,FALSE()) -> 5 | F12: 1 | G12: 1 | H12: =D12+E12+F12+G12 -> 22 | I12: =D12+E12+F12 -> 21 | J12: 0 | K12: =H12*(J12*manut_dia+(C12-J12)*manut_med) -> 411.4 | L12: =I12*J12*alojamiento -> 0 | M12: =C12*bus_dia*CEILING(I12/cap_bus,1) -> 700 | N12: =K12+L12+M12 -> 1111.4 | O12: 0.6 | P12: =N12*O12 -> 666.84 | Q12: =N12*(1-O12) -> 444.56 | R12: P2
A13: A7 | B13: 1 | C13: =VLOOKUP(A13,ACTIVIDADES!$A$5:$D$50,4,FALSE()) -> 1 | D13: =VLOOKUP(A13,ACTIVIDADES!$A$5:$F$50,6,FALSE()) -> 15 | E13: =VLOOKUP(A13,ACTIVIDADES!$A$5:$G$50,7,FALSE()) -> 4 | F13: 1 | G13: 1 | H13: =D13+E13+F13+G13 -> 21 | I13: =D13+E13+F13 -> 20 | J13: 0 | K13: =H13*(J13*manut_dia+(C13-J13)*manut_med) -> 392.7 | L13: =I13*J13*alojamiento -> 0 | M13: =C13*bus_dia*CEILING(I13/cap_bus,1) -> 700 | N13: =K13+L13+M13 -> 1092.7 | O13: 0.6 | P13: =N13*O13 -> 655.62 | Q13: =N13*(1-O13) -> 437.08 | R13: P2
A14: A8 | B14: 1 | C14: =VLOOKUP(A14,ACTIVIDADES!$A$5:$D$50,4,FALSE()) -> 2 | D14: =VLOOKUP(A14,ACTIVIDADES!$A$5:$F$50,6,FALSE()) -> 12 | E14: =VLOOKUP(A14,ACTIVIDADES!$A$5:$G$50,7,FALSE()) -> 6 | F14: 1 | G14: 1 | H14: =D14+E14+F14+G14 -> 20 | I14: =D14+E14+F14 -> 19 | J14: 1 | K14: =H14*(J14*manut_dia+(C14-J14)*manut_med) -> 1122 | L14: =I14*J14*alojamiento -> 1253.43 | M14: =C14*bus_dia*CEILING(I14/cap_bus,1) -> 1400 | N14: =K14+L14+M14 -> 3775.43 | O14: 0.7 | P14: =N14*O14 -> 2642.801 | Q14: =N14*(1-O14) -> 1132.629 | R14: P1
A15: A9 | B15: 1 | C15: =VLOOKUP(A15,ACTIVIDADES!$A$5:$D$50,4,FALSE()) -> 1 | D15: =VLOOKUP(A15,ACTIVIDADES!$A$5:$F$50,6,FALSE()) -> 12 | E15: =VLOOKUP(A15,ACTIVIDADES!$A$5:$G$50,7,FALSE()) -> 6 | F15: 1 | G15: 1 | H15: =D15+E15+F15+G15 -> 20 | I15: =D15+E15+F15 -> 19 | J15: 0 | K15: =H15*(J15*manut_dia+(C15-J15)*manut_med) -> 374 | L15: =I15*J15*alojamiento -> 0 | M15: =C15*bus_dia*CEILING(I15/cap_bus,1) -> 700 | N15: =K15+L15+M15 -> 1074 | O15: 0.7 | P15: =N15*O15 -> 751.8 | Q15: =N15*(1-O15) -> 322.2 | R15: P1
A16: A10 | B16: 1 | C16: =VLOOKUP(A16,ACTIVIDADES!$A$5:$D$50,4,FALSE()) -> 2 | D16: =VLOOKUP(A16,ACTIVIDADES!$A$5:$F$50,6,FALSE()) -> 12 | E16: =VLOOKUP(A16,ACTIVIDADES!$A$5:$G$50,7,FALSE()) -> 8 | F16: 1 | G16: 2 | H16: =D16+E16+F16+G16 -> 23 | I16: =D16+E16+F16 -> 21 | J16: 1 | K16: =H16*(J16*manut_dia+(C16-J16)*manut_med) -> 1290.3 | L16: =I16*J16*alojamiento -> 1385.37 | M16: =C16*bus_dia*CEILING(I16/cap_bus,1) -> 1400 | N16: =K16+L16+M16 -> 4075.67 | O16: 0.4 | P16: =N16*O16 -> 1630.268 | Q16: =N16*(1-O16) -> 2445.402 | R16: P2
... A32: A25 | B32: 1 | C32: =VLOOKUP(A32,ACTIVIDADES!$A$5:$D$50,4,FALSE()) -> 1 | D32: =VLOOKUP(A32,ACTIVIDADES!$A$5:$F$50,6,FALSE()) -> 12 | E32: =VLOOKUP(A32,ACTIVIDADES!$A$5:$G$50,7,FALSE()) -> 6 | F32: 1 | G32: 1 | H32: =D32+E32+F32+G32 -> 20 | I32: =D32+E32+F32 -> 19 | J32: 0 | K32: =H32*(J32*manut_dia+(C32-J32)*manut_med) -> 374 | L32: =I32*J32*alojamiento -> 0 | M32: =C32*bus_dia*CEILING(I32/cap_bus,1) -> 700 | N32: =K32+L32+M32 -> 1074 | O32: 0.85 | P32: =N32*O32 -> 912.9 | Q32: =N32*(1-O32) -> 161.1 | R32: P1
B33: TOTAL B.1 | D33: =SUM(D5:D32) -> 408 | E33: =SUM(E5:E32) -> 157 | F33: =SUM(F5:F32) -> 31 | G33: =SUM(G5:G32) -> 32 | K33: =SUM(K5:K32) -> 18400.8 | L33: =SUM(L5:L32) -> 11082.96 | M33: =SUM(M5:M32) -> 25200 | N33: =SUM(N5:N32) -> 54683.76 | P33: =SUM(P5:P32) -> 30874.23 | Q33: =SUM(Q5:Q32) -> 23809.53
B34: Subtotal P1 | N34: =SUMIFS(N5:N32,R5:R32,"P1") -> 17540.91
B35: Subtotal P2 | N35: =SUMIFS(N5:N32,R5:R32,"P2") -> 37142.85

Sheet MATERIALES
A1: MATERIALES — B.2 · B.3 · B.4 · B.5 · B.6 · B.7
A2: Cada concepto con su Periodo (input azul). Las partidas que cubren el proyecto entero se desdoblan en filas P1 y P2.
A4: Partida | B4: Concepto | C4: Cantidad | D4: € unit. | E4: Coste | F4: Tope | G4: % tope | H4: UPM % | I4: UPM € | J4: Periodo
A5: B.2 | B5: Entornos virtuales — plataforma online (LMS, casos, recursos) | C5: 1 | D5: 1000 | E5: =C5*D5 -> 1000 | F5: =tope_ent -> 5000 | G5: =E5/F5 -> 0.2 | H5: 0.5 | I5: =E5*H5 -> 500 | J5: P1
A6: B.3 | B6: Material fungible P1 — cuadernos, USB, dossier (24 part. × 35 €) | C6: 24 | D6: 35 | E6: =C6*D6 -> 840 | F6: — | G6: — | H6: 0.4 | I6: =E6*H6 -> 336 | J6: P1
A7: B.3 | B7: Material fungible P2 — cuadernos, USB, dossier (36 part. × 35 €) | C7: 36 | D7: 35 | E7: =C7*D7 -> 1260 | F7: — | G7: — | H7: 0.4 | I7: =E7*H7 -> 504 | J7: P2
A8: B.4 | B8: Seguros P1 — RC actividades demostrativas | C8: 1 | D8: 400 | E8: =C8*D8 -> 400 | F8: — | G8: — | H8: 0.5 | I8: =E8*H8 -> 200 | J8: P1
A9: B.4 | B9: Seguros P2 — RC actividades demostrativas | C9: 1 | D9: 600 | E9: =C9*D9 -> 600 | F9: — | G9: — | H9: 0.5 | I9: =E9*H9 -> 300 | J9: P2
A10: B.5 | B10: Auditoría — auditor externo (1 % subvención, máx. 5.000 €) | C10: 1 | D10: 2800 | E10: =C10*D10 -> 2800 | F10: =tope_aud -> 5000 | G10: =E10/F10 -> 0.56 | H10: 0.5 | I10: =E10*H10 -> 1400 | J10: P2
A11: B.6 | B11: Alquileres P1 — equipos formación, salas | C11: 1 | D11: 1500 | E11: =C11*D11 -> 1500 | F11: — | G11: — | H11: 0.5 | I11: =E11*H11 -> 750 | J11: P1
A12: B.6 | B12: Alquileres P2 — andamios domo, herramientas puntuales | C12: 1 | D12: 3500 | E12: =C12*D12 -> 3500 | F12: — | G12: — | H12: 0.5 | I12: =E12*H12 -> 1750 | J12: P2
A13: B.7 | B13: Comunicación P1 — web, RRSS, podcast, vídeo arranque | C13: 1 | D13: 500 | E13: =C13*D13 -> 500 | F13: — | G13: — | H13: 0.5 | I13: =E13*H13 -> 250 | J13: P1
A14: B.7 | B14: Comunicación P2 — roll-ups, dossier final, jornada cierre | C14: 1 | D14: 1000 | E14: =C14*D14 -> 1000 | F14: — | G14: — | H14: 0.5 | I14: =E14*H14 -> 500 | J14: P2
B15: TOTAL B (sin B.1) | E15: =SUM(E5:E14) -> 13400 | I15: =SUM(I5:I14) -> 6490

Sheet INVERSIONES
A1: INVERSIONES — C.1 (amortización) · C.2 (otras inversiones)
A3: C.1 · BIENES INVENTARIABLES — amortización separada por meses de cada periodo (P1=7m · P2=10m)
A4: Concepto | B4: Descripción | C4: Coste compra | D4: Vida útil (m) | E4: Cuota P1 (7 m) | F4: Cuota P2 (10 m) | G4: Cuota total | H4: UPM % | I4: UPM € | J4: COPR € | K4: Notas
A5: Dron multispectral | B5: DJI Mavic 3M + cámara multiespectral | C5: 8000 | D5: 60 | E5: =C5/D5*meses_p1 -> 933.33333 | F5: =C5/D5*meses_p2 -> 1333.3333 | G5: =E5+F5 -> 2266.6667 | H5: 1 | I5: =G5*H5 -> 2266.6667 | J5: =G5*(1-H5) -> 0 | K5: Activo UPM (drones GeoSo2)
A6: Sensores IoT | B6: Lote 20 sensores LoRa humedad/meteo | C6: 5000 | D6: 60 | E6: =C6/D6*meses_p1 -> 583.33333 | F6: =C6/D6*meses_p2 -> 833.33333 | G6: =E6+F6 -> 1416.6667 | H6: 1 | I6: =G6*H6 -> 1416.6667 | J6: =G6*(1-H6) -> 0 | K6: Quedan en parcela; activos UPM
A7: Software de cálculo de estructuras | B7: Licencia anual de software estructural (cálculo del domo geodésico) | C7: 3000 | D7: 17 | E7: =C7/D7*meses_p1 -> 1235.2941 | F7: =C7/D7*meses_p2 -> 1764.7059 | G7: =E7+F7 -> 3000 | H7: 1 | I7: =G7*H7 -> 3000 | J7: =G7*(1-H7) -> 0 | K7: Licencia anual prorrateada al periodo
A8: Servidor/gateway IoT | B8: Gateway LoRa + servidor backend | C8: 2000 | D8: 60 | E8: =C8/D8*meses_p1 -> 233.33333 | F8: =C8/D8*meses_p2 -> 333.33333 | G8: =E8+F8 -> 566.66667 | H8: 1 | I8: =G8*H8 -> 566.66667 | J8: =G8*(1-H8) -> 0 | K8: Activo UPM
B9: TOTAL C.1 | E9: =SUM(E5:E8) -> 2985.2941 | F9: =SUM(F5:F8) -> 4264.7059 | G9: =SUM(G5:G8) -> 7250 | I9: =SUM(I5:I8) -> 7250 | J9: =SUM(J5:J8) -> 0
A12: C.2 · OTRAS INVERSIONES — cada ítem con su Periodo (P1/P2)
A13: Concepto | B13: Descripción | C13: Cantidad | D13: € unit. | E13: Coste total | F13: Periodo | G13: UPM % | H13: UPM € | I13: COPR € | J13: Vinculación a Ai
A14: Cimentación domo | B14: Zapatas, hormigón armado, replanteo del polígono geodésico | C14: 1 | D14: 2500 | E14: =C14*D14 -> 2500 | F14: P2 | G14: 0.3 | H14: =E14*G14 -> 750 | I14: =E14*(1-G14) -> 1750 | J14: A10–A11
A15: Estructura del domo | B15: Madera precortada + anclajes + herrajes metálicos | C15: 1 | D15: 13500 | E15: =C15*D15 -> 13500 | F15: P2 | G15: 0.3 | H15: =E15*G15 -> 4050 | I15: =E15*(1-G15) -> 9450 | J15: A10–A11
A16: Cubierta y suelos del domo | B16: Cubierta exterior + acabado interior del suelo | C16: 1 | D16: 4000 | E16: =C16*D16 -> 4000 | F16: P2 | G16: 0.3 | H16: =E16*G16 -> 1200 | I16: =E16*(1-G16) -> 2800 | J16: A12
A17: Aislamiento del domo (hidrófugo + térmico) | B17: Corcho aglomerado + impermeabilización exterior | C17: 1 | D17: 3500 | E17: =C17*D17 -> 3500 | F17: P2 | G17: 0.3 | H17: =E17*G17 -> 1050 | I17: =E17*(1-G17) -> 2450 | J17: A13
A18: Ventanas del domo | B18: Ventanas + ventilación pasiva | C18: 1 | D18: 2500 | E18: =C18*D18 -> 2500 | F18: P2 | G18: 0.3 | H18: =E18*G18 -> 750 | I18: =E18*(1-G18) -> 1750 | J18: A12–A13
A19: Cableado y sistema solar | B19: Pre-cableado eléctrico + paneles FV + inversor + baterías | C19: 1 | D19: 8000 | E19: =C19*D19 -> 8000 | F19: P2 | G19: 0.6 | H19: =E19*G19 -> 4800 | I19: =E19*(1-G19) -> 3200 | J19: A14
A20: Conectividad satelital | B20: Starlink + soporte + cuotas 17 m | C20: 1 | D20: 2500 | E20: =C20*D20 -> 2500 | F20: P2 | G20: 0.5 | H20: =E20*G20 -> 1250 | I20: =E20*(1-G20) -> 1250 | J20: A15
A21: Semillas y sustratos | B21: Plantel y abonos 2 ciclos | C21: 1 | D21: 2000 | E21: =C21*D21 -> 2000 | F21: P2 | G21: 0.2 | H21: =E21*G21 -> 400 | I21: =E21*(1-G21) -> 1600 | J21: F8 ciclo
A22: Sensórica y comunicaciones de riego | B22: Sensores humedad de suelo + módulo LoRa específico riego | C22: 1 | D22: 1500 | E22: =C22*D22 -> 1500 | F22: P2 | G22: 0.7 | H22: =E22*G22 -> 1050 | I22: =E22*(1-G22) -> 450 | J22: A5/A6
A23: Material de riego | B23: Electroválvulas, tuberías, goteros, filtros | C23: 1 | D23: 2000 | E23: =C23*D23 -> 2000 | F23: P2 | G23: 0.4 | H23: =E23*G23 -> 800 | I23: =E23*(1-G23) -> 1200 | J23: A5/A6
B24: TOTAL C.2 | E24: =SUM(E14:E23) -> 42000 | H24: =SUM(H14:H23) -> 16100 | I24: =SUM(I14:I23) -> 25900

Sheet PRESUPUESTO
A1: PRESUPUESTO — desglose por fase y por actividad
A2: Cada actividad se imputa a P1 o P2 según el periodo de su PRIMERA edición. Los costes transversales (A.5, B.x, C.x, indirectos) se asignan explícitamente a cada fase. SIN porcentajes arbitrarios.
A4: FASE 1 (P1) — Costes por actividad y transversales
A5: Id | B5: Actividad | C5: A.1 | D5: A.2 | E5: A.3 | F5: A.4 | G5: Subtotal personal Ai
A6: A1 | B6: =VLOOKUP(A6,ACTIVIDADES!$A$5:$C$50,3,FALSE()) -> Concepto NEB aplicado a la microexplotación alcarreña | C6: =SUMIF(PERSONAL!$A$66:$A$67,A6,PERSONAL!$H$66:$H$67) -> 720 | D6: =SUMIF(PERSONAL!$A$73:$A$76,A6,PERSONAL!$H$73:$H$76) -> 0 | E6: =SUMIF(PERSONAL!$A$36:$A$60,A6,PERSONAL!$K$36:$K$60) -> 419.7 | F6: =SUMIF(PERSONAL!$A$6:$A$30,A6,PERSONAL!$K$6:$K$30) -> 136.86 | G6: =C6+D6+E6+F6 -> 1276.56
A7: A2 | B7: =VLOOKUP(A7,ACTIVIDADES!$A$5:$C$50,3,FALSE()) -> Cumplimentación CUE/SIEX | C7: =SUMIF(PERSONAL!$A$66:$A$67,A7,PERSONAL!$H$66:$H$67) -> 0 | D7: =SUMIF(PERSONAL!$A$73:$A$76,A7,PERSONAL!$H$73:$H$76) -> 0 | E7: =SUMIF(PERSONAL!$A$36:$A$60,A7,PERSONAL!$K$36:$K$60) -> 1175.16 | F7: =SUMIF(PERSONAL!$A$6:$A$30,A7,PERSONAL!$K$6:$K$30) -> 1218.96 | G7: =C7+D7+E7+F7 -> 2394.12
A8: A3 | B8: =VLOOKUP(A8,ACTIVIDADES!$A$5:$C$50,3,FALSE()) -> SIGPAC y declaración | C8: =SUMIF(PERSONAL!$A$66:$A$67,A8,PERSONAL!$H$66:$H$67) -> 0 | D8: =SUMIF(PERSONAL!$A$73:$A$76,A8,PERSONAL!$H$73:$H$76) -> 0 | E8: =SUMIF(PERSONAL!$A$36:$A$60,A8,PERSONAL!$K$36:$K$60) -> 419.7 | F8: =SUMIF(PERSONAL!$A$6:$A$30,A8,PERSONAL!$K$6:$K$30) -> 497.56 | G8: =C8+D8+E8+F8 -> 917.26
A9: A4 | B9: =VLOOKUP(A9,ACTIVIDADES!$A$5:$C$50,3,FALSE()) -> SIG QGIS + NDVI en campo | C9: =SUMIF(PERSONAL!$A$66:$A$67,A9,PERSONAL!$H$66:$H$67) -> 0 | D9: =SUMIF(PERSONAL!$A$73:$A$76,A9,PERSONAL!$H$73:$H$76) -> 0 | E9: =SUMIF(PERSONAL!$A$36:$A$60,A9,PERSONAL!$K$36:$K$60) -> 839.4 | F9: =SUMIF(PERSONAL!$A$6:$A$30,A9,PERSONAL!$K$6:$K$30) -> 665.44 | G9: =C9+D9+E9+F9 -> 1504.84
A10: A8 | B10: =VLOOKUP(A10,ACTIVIDADES!$A$5:$C$50,3,FALSE()) -> CAD instalaciones de madera | C10: =SUMIF(PERSONAL!$A$66:$A$67,A10,PERSONAL!$H$66:$H$67) -> 0 | D10: =SUMIF(PERSONAL!$A$73:$A$76,A10,PERSONAL!$H$73:$H$76) -> 0 | E10: =SUMIF(PERSONAL!$A$36:$A$60,A10,PERSONAL!$K$36:$K$60) -> 839.4 | F10: =SUMIF(PERSONAL!$A$6:$A$30,A10,PERSONAL!$K$6:$K$30) -> 167.88 | G10: =C10+D10+E10+F10 -> 1007.28
A11: A9 | B11: =VLOOKUP(A11,ACTIVIDADES!$A$5:$C$50,3,FALSE()) -> Cálculo y planos del domo geodésico | C11: =SUMIF(PERSONAL!$A$66:$A$67,A11,PERSONAL!$H$66:$H$67) -> 0 | D11: =SUMIF(PERSONAL!$A$73:$A$76,A11,PERSONAL!$H$73:$H$76) -> 0 | E11: =SUMIF(PERSONAL!$A$36:$A$60,A11,PERSONAL!$K$36:$K$60) -> 419.7 | F11: =SUMIF(PERSONAL!$A$6:$A$30,A11,PERSONAL!$K$6:$K$30) -> 167.88 | G11: =C11+D11+E11+F11 -> 587.58
A12: A24 | B12: =VLOOKUP(A12,ACTIVIDADES!$A$5:$C$50,3,FALSE()) -> Configuración del cuaderno digital open-source para microexplotación hortícola (FarmOS adaptado · TRL5 → TRL7) | C12: =SUMIF(PERSONAL!$A$66:$A$67,A12,PERSONAL!$H$66:$H$67) -> 0 | D12: =SUMIF(PERSONAL!$A$73:$A$76,A12,PERSONAL!$H$73:$H$76) -> 0 | E12: =SUMIF(PERSONAL!$A$36:$A$60,A12,PERSONAL!$K$36:$K$60) -> 419.7 | F12: =SUMIF(PERSONAL!$A$6:$A$30,A12,PERSONAL!$K$6:$K$30) -> 10541.2 | G12: =C12+D12+E12+F12 -> 10960.9
A13: A25 | B13: =VLOOKUP(A13,ACTIVIDADES!$A$5:$C$50,3,FALSE()) -> Configuración del SIG open-source (QGIS + QField) para microexplotaciones (TRL5 → TRL7) | C13: =SUMIF(PERSONAL!$A$66:$A$67,A13,PERSONAL!$H$66:$H$67) -> 0 | D13: =SUMIF(PERSONAL!$A$73:$A$76,A13,PERSONAL!$H$73:$H$76) -> 0 | E13: =SUMIF(PERSONAL!$A$36:$A$60,A13,PERSONAL!$K$36:$K$60) -> 419.7 | F13: =SUMIF(PERSONAL!$A$6:$A$30,A13,PERSONAL!$K$6:$K$30) -> 9717 | G13: =C13+D13+E13+F13 -> 10136.7
B14: Subtotal personal por actividad | C14: =SUM(C6:C13) -> 720 | D14: =SUM(D6:D13) -> 0 | E14: =SUM(E6:E13) -> 4952.46 | F14: =SUM(F6:F13) -> 23112.78 | G14: =SUM(G6:G13) -> 28785.24
B16: COSTES TRANSVERSALES P1
B17: Concepto | C17: Total | D17: —
B18: A.5 Coordinación | C18: =PERSONAL!$H$82+PERSONAL!$H$84 -> 12535.04
B19: B.1 Viajes y dietas | C19: =VIAJES!$N$34 -> 17540.91
B20: B.2 Entornos virtuales | C20: =SUMIFS(MATERIALES!$E$5:$E$14,MATERIALES!$A$5:$A$14,"B.2",MATERIALES!$J$5:$J$14,"P1") -> 1000
B21: B.3 Material fungible | C21: =SUMIFS(MATERIALES!$E$5:$E$14,MATERIALES!$A$5:$A$14,"B.3",MATERIALES!$J$5:$J$14,"P1") -> 840
B22: B.4 Seguros | C22: =SUMIFS(MATERIALES!$E$5:$E$14,MATERIALES!$A$5:$A$14,"B.4",MATERIALES!$J$5:$J$14,"P1") -> 400
B23: B.5 Auditoría | C23: =SUMIFS(MATERIALES!$E$5:$E$14,MATERIALES!$A$5:$A$14,"B.5",MATERIALES!$J$5:$J$14,"P1") -> 0
B24: B.6 Alquileres | C24: =SUMIFS(MATERIALES!$E$5:$E$14,MATERIALES!$A$5:$A$14,"B.6",MATERIALES!$J$5:$J$14,"P1") -> 1500
B25: B.7 Comunicación | C25: =SUMIFS(MATERIALES!$E$5:$E$14,MATERIALES!$A$5:$A$14,"B.7",MATERIALES!$J$5:$J$14,"P1") -> 500
B26: C.1 Bienes inventariables (cuota) | C26: =INVERSIONES!$E$9 -> 2985.2941
B27: C.2 Otras inversiones | C27: =SUMIFS(INVERSIONES!$E$14:$E$23,INVERSIONES!$F$14:$F$23,"P1") -> 0
B28: Costes indirectos (15 % personal directo de la fase) | C28: =($G$14+C18)*tasa_ind -> 6198.042
B29: Subtotal transversales | C29: =SUM(C18:C28) -> 43499.286
B30: TOTAL P1 | C30: =$G$14+$C$29 -> 72284.526
A32: FASE 2 (P2) — Costes por actividad y transversales
A33: Id | B33: Actividad | C33: A.1 | D33: A.2 | E33: A.3 | F33: A.4 | G33: Subtotal personal Ai
A34: A5 | B34: =VLOOKUP(A34,ACTIVIDADES!$A$5:$C$50,3,FALSE()) -> Despliegue red IoT en huerta | C34: =SUMIF(PERSONAL!$A$66:$A$67,A34,PERSONAL!$H$66:$H$67) -> 0 | D34: =SUMIF(PERSONAL!$A$73:$A$76,A34,PERSONAL!$H$73:$H$76) -> 0 | E34: =SUMIF(PERSONAL!$A$36:$A$60,A34,PERSONAL!$K$36:$K$60) -> 839.4 | F34: =SUMIF(PERSONAL!$A$6:$A$30,A34,PERSONAL!$K$6:$K$30) -> 1648.4 | G34: =C34+D34+E34+F34 -> 2487.8
A35: A6 | B35: =VLOOKUP(A35,ACTIVIDADES!$A$5:$C$50,3,FALSE()) -> Demostración riego automatizado | C35: =SUMIF(PERSONAL!$A$66:$A$67,A35,PERSONAL!$H$66:$H$67) -> 0 | D35: =SUMIF(PERSONAL!$A$73:$A$76,A35,PERSONAL!$H$73:$H$76) -> 0 | E35: =SUMIF(PERSONAL!$A$36:$A$60,A35,PERSONAL!$K$36:$K$60) -> 587.58 | F35: =SUMIF(PERSONAL!$A$6:$A$30,A35,PERSONAL!$K$6:$K$30) -> 659.36 | G35: =C35+D35+E35+F35 -> 1246.94
A36: A7 | B36: =VLOOKUP(A36,ACTIVIDADES!$A$5:$C$50,3,FALSE()) -> Volcado automatizado al CUE | C36: =SUMIF(PERSONAL!$A$66:$A$67,A36,PERSONAL!$H$66:$H$67) -> 0 | D36: =SUMIF(PERSONAL!$A$73:$A$76,A36,PERSONAL!$H$73:$H$76) -> 0 | E36: =SUMIF(PERSONAL!$A$36:$A$60,A36,PERSONAL!$K$36:$K$60) -> 419.7 | F36: =SUMIF(PERSONAL!$A$6:$A$30,A36,PERSONAL!$K$6:$K$30) -> 335.76 | G36: =C36+D36+E36+F36 -> 755.46
A37: A10 | B37: =VLOOKUP(A37,ACTIVIDADES!$A$5:$C$50,3,FALSE()) -> Levantamiento de la estructura del domo | C37: =SUMIF(PERSONAL!$A$66:$A$67,A37,PERSONAL!$H$66:$H$67) -> 0 | D37: =SUMIF(PERSONAL!$A$73:$A$76,A37,PERSONAL!$H$73:$H$76) -> 4500 | E37: =SUMIF(PERSONAL!$A$36:$A$60,A37,PERSONAL!$K$36:$K$60) -> 839.4 | F37: =SUMIF(PERSONAL!$A$6:$A$30,A37,PERSONAL!$K$6:$K$30) -> 2142.36 | G37: =C37+D37+E37+F37 -> 7481.76
A38: A11 | B38: =VLOOKUP(A38,ACTIVIDADES!$A$5:$C$50,3,FALSE()) -> Anclajes y fijaciones del domo | C38: =SUMIF(PERSONAL!$A$66:$A$67,A38,PERSONAL!$H$66:$H$67) -> 0 | D38: =SUMIF(PERSONAL!$A$73:$A$76,A38,PERSONAL!$H$73:$H$76) -> 2700 | E38: =SUMIF(PERSONAL!$A$36:$A$60,A38,PERSONAL!$K$36:$K$60) -> 419.7 | F38: =SUMIF(PERSONAL!$A$6:$A$30,A38,PERSONAL!$K$6:$K$30) -> 1046.24 | G38: =C38+D38+E38+F38 -> 4165.94
A39: A12 | B39: =VLOOKUP(A39,ACTIVIDADES!$A$5:$C$50,3,FALSE()) -> Cubierta y entelado del domo | C39: =SUMIF(PERSONAL!$A$66:$A$67,A39,PERSONAL!$H$66:$H$67) -> 0 | D39: =SUMIF(PERSONAL!$A$73:$A$76,A39,PERSONAL!$H$73:$H$76) -> 2700 | E39: =SUMIF(PERSONAL!$A$36:$A$60,A39,PERSONAL!$K$36:$K$60) -> 839.4 | F39: =SUMIF(PERSONAL!$A$6:$A$30,A39,PERSONAL!$K$6:$K$30) -> 523.12 | G39: =C39+D39+E39+F39 -> 4062.52
A40: A13 | B40: =VLOOKUP(A40,ACTIVIDADES!$A$5:$C$50,3,FALSE()) -> Acabado e impermeabilización con corcho | C40: =SUMIF(PERSONAL!$A$66:$A$67,A40,PERSONAL!$H$66:$H$67) -> 0 | D40: =SUMIF(PERSONAL!$A$73:$A$76,A40,PERSONAL!$H$73:$H$76) -> 0 | E40: =SUMIF(PERSONAL!$A$36:$A$60,A40,PERSONAL!$K$36:$K$60) -> 419.7 | F40: =SUMIF(PERSONAL!$A$6:$A$30,A40,PERSONAL!$K$6:$K$30) -> 311.44 | G40: =C40+D40+E40+F40 -> 731.14
A41: A14 | B41: =VLOOKUP(A41,ACTIVIDADES!$A$5:$C$50,3,FALSE()) -> Instalación fotovoltaica | C41: =SUMIF(PERSONAL!$A$66:$A$67,A41,PERSONAL!$H$66:$H$67) -> 0 | D41: =SUMIF(PERSONAL!$A$73:$A$76,A41,PERSONAL!$H$73:$H$76) -> 1440 | E41: =SUMIF(PERSONAL!$A$36:$A$60,A41,PERSONAL!$K$36:$K$60) -> 419.7 | F41: =SUMIF(PERSONAL!$A$6:$A$30,A41,PERSONAL!$K$6:$K$30) -> 311.44 | G41: =C41+D41+E41+F41 -> 2171.14
A42: A15 | B42: =VLOOKUP(A42,ACTIVIDADES!$A$5:$C$50,3,FALSE()) -> Conectividad satelital y red | C42: =SUMIF(PERSONAL!$A$66:$A$67,A42,PERSONAL!$H$66:$H$67) -> 0 | D42: =SUMIF(PERSONAL!$A$73:$A$76,A42,PERSONAL!$H$73:$H$76) -> 0 | E42: =SUMIF(PERSONAL!$A$36:$A$60,A42,PERSONAL!$K$36:$K$60) -> 419.7 | F42: =SUMIF(PERSONAL!$A$6:$A$30,A42,PERSONAL!$K$6:$K$30) -> 223.84 | G42: =C42+D42+E42+F42 -> 643.54
A43: A16 | B43: =VLOOKUP(A43,ACTIVIDADES!$A$5:$C$50,3,FALSE()) -> Despliegue de sensores en la huerta | C43: =SUMIF(PERSONAL!$A$66:$A$67,A43,PERSONAL!$H$66:$H$67) -> 0 | D43: =SUMIF(PERSONAL!$A$73:$A$76,A43,PERSONAL!$H$73:$H$76) -> 0 | E43: =SUMIF(PERSONAL!$A$36:$A$60,A43,PERSONAL!$K$36:$K$60) -> 839.4 | F43: =SUMIF(PERSONAL!$A$6:$A$30,A43,PERSONAL!$K$6:$K$30) -> 771.28 | G43: =C43+D43+E43+F43 -> 1610.68
...
